<mujoco model="fruit_gym">
  <compiler angle="radian" meshdir="assets/"/>

  <option noslip_tolerance="0" integrator="implicitfast" noslip_iterations="5">
  </option>

  <size memory="100M"/>

  <visual>
    <global azimuth="120" elevation="-20"/>
    <quality shadowsize="8192"/>
    <headlight ambient="0.3 0.3 0.3" diffuse="0.6 0.6 0.6" specular="0.1 0.1 0.1"/>
    <rgba haze="0.15 0.25 0.35 1"/>
  </visual>

  <statistic extent="1" center="0.3 0 0.4"/>

  <default>
    <default class="panda">
      <material shininess="0.25"/>
      <joint range="-2.8973 2.8973" armature="0.1" damping="1"/>
      <default class="finger">
        <joint type="slide" range="0 0.04"/>
      </default>
      <default class="visual">
        <geom type="mesh" contype="0" conaffinity="0" group="2"/>
      </default>
      <default class="collision">
        <geom type="mesh" group="3"/>
      </default>
    </default>
    <default class="d435i">
      <material specular="0" shininess="0.25"/>
      <default class="d435i_visual">
        <geom type="mesh" contype="0" conaffinity="0" group="2"/>
      </default>
      <default class="d435i_collision">
        <geom type="mesh" group="3"/>
      </default>
    </default>
  </default>

  <custom>
    <text name="composite_a" data="rope_a"/>
    <text name="composite_b" data="rope_b"/>
    <text name="composite_c" data="rope_c"/>
  </custom>

  <asset>
    <texture type="skybox" name="space_2" file="textures/skyboxes/space_2.png" gridsize="3 4" gridlayout=".U..LFRB.D.."/>
    <texture type="2d" name="Grass001" file="textures/Grass001_2K-PNG_Color.png"/>
    <texture name="strawb_leaves" type="2d" file="textures/strawberry_leaves.png"/>


    <material name="white" class="panda"/>
    <material name="off_white" class="panda" rgba="0.901961 0.921569 0.929412 1"/>
    <material name="black" class="panda" rgba="0.25 0.25 0.25 1"/>
    <material name="green" class="panda" rgba="0 1 0 1"/>
    <material name="light_blue" class="panda" rgba="0.039216 0.541176 0.780392 1"/>
    <material name="Black_Acrylic" class="d435i" rgba="0.07036 0.07036 0.07036 1"/>
    <material name="Cameras_Gray" class="d435i" rgba="0.296138 0.296138 0.296138 1"/>
    <material name="IR_Emitter_Lens" class="d435i" rgba="0.28744 0.665387 0.327778 1"/>
    <material name="IR_Lens" class="d435i" rgba="0.035601 0.035601 0.035601 1"/>
    <material name="IR_Rim" class="d435i" rgba="0.799102 0.806952 0.799103 1"/>
    <material name="Metal_Casing" class="d435i"/>
    <material name="RGB_Pupil" class="d435i" rgba="0.08714 0.002866 0.009346 1"/>
    <material name="skybox" texture="space_2"/>
    <material name="floor" texture="Grass001" specular="1" shininess="1"/>
    <material name="strawberry_material" rgba="0.55 0.1 0.1 1" shininess="0.01" specular="0.01" reflectance="0.05" texuniform="true"/>
    <material name="strawberry_leaves" texture="strawb_leaves" shininess="0.1" specular="0.1" reflectance="0.5" texuniform="true"/>
    
    <mesh name="link0_c" file="link0.stl"/>
    <mesh name="link1_c" file="link1.stl"/>
    <mesh name="link2_c" file="link2.stl"/>
    <mesh name="link3_c" file="link3.stl"/>
    <mesh name="link4_c" file="link4.stl"/>
    <mesh name="link5_c0" file="link5_collision_0.obj"/>
    <mesh name="link5_c1" file="link5_collision_1.obj"/>
    <mesh name="link5_c2" file="link5_collision_2.obj"/>
    <mesh name="link6_c" file="link6.stl"/>
    <mesh name="link7_c" file="link7.stl"/>
    <mesh name="camera_mount_c" file="camera_mount_collision_straight.stl"/>
    <mesh name="hand_c" file="hand.stl"/>
    <mesh name="gripper_long_inner" file="gripper_long_inner.stl"/>
    <mesh name="gripper_long_outer" file="gripper_long_outer.stl"/>
    <mesh name="gripper_long" file="gripper_long.stl"/>
    <mesh name="link0_0" file="link0_0.obj"/>
    <mesh name="link0_1" file="link0_1.obj"/>
    <mesh name="link0_2" file="link0_2.obj"/>
    <mesh name="link0_3" file="link0_3.obj"/>
    <mesh name="link0_4" file="link0_4.obj"/>
    <mesh name="link0_5" file="link0_5.obj"/>
    <mesh name="link0_7" file="link0_7.obj"/>
    <mesh name="link0_8" file="link0_8.obj"/>
    <mesh name="link0_9" file="link0_9.obj"/>
    <mesh name="link0_10" file="link0_10.obj"/>
    <mesh name="link0_11" file="link0_11.obj"/>
    <mesh name="link1" file="link1.obj"/>
    <mesh name="link2" file="link2.obj"/>
    <mesh name="link3_0" file="link3_0.obj"/>
    <mesh name="link3_1" file="link3_1.obj"/>
    <mesh name="link3_2" file="link3_2.obj"/>
    <mesh name="link3_3" file="link3_3.obj"/>
    <mesh name="link4_0" file="link4_0.obj"/>
    <mesh name="link4_1" file="link4_1.obj"/>
    <mesh name="link4_2" file="link4_2.obj"/>
    <mesh name="link4_3" file="link4_3.obj"/>
    <mesh name="link5_0" file="link5_0.obj"/>
    <mesh name="link5_1" file="link5_1.obj"/>
    <mesh name="link5_2" file="link5_2.obj"/>
    <mesh name="link6_0" file="link6_0.obj"/>
    <mesh name="link6_1" file="link6_1.obj"/>
    <mesh name="link6_2" file="link6_2.obj"/>
    <mesh name="link6_3" file="link6_3.obj"/>
    <mesh name="link6_4" file="link6_4.obj"/>
    <mesh name="link6_5" file="link6_5.obj"/>
    <mesh name="link6_6" file="link6_6.obj"/>
    <mesh name="link6_7" file="link6_7.obj"/>
    <mesh name="link6_8" file="link6_8.obj"/>
    <mesh name="link6_9" file="link6_9.obj"/>
    <mesh name="link6_10" file="link6_10.obj"/>
    <mesh name="link6_11" file="link6_11.obj"/>
    <mesh name="link6_12" file="link6_12.obj"/>
    <mesh name="link6_13" file="link6_13.obj"/>
    <mesh name="link6_14" file="link6_14.obj"/>
    <mesh name="link6_15" file="link6_15.obj"/>
    <mesh name="link6_16" file="link6_16.obj"/>
    <mesh name="link7_0" file="link7_0.obj"/>
    <mesh name="link7_1" file="link7_1.obj"/>
    <mesh name="link7_2" file="link7_2.obj"/>
    <mesh name="link7_3" file="link7_3.obj"/>
    <mesh name="link7_4" file="link7_4.obj"/>
    <mesh name="link7_5" file="link7_5.obj"/>
    <mesh name="link7_6" file="link7_6.obj"/>
    <mesh name="link7_7" file="link7_7.obj"/>
    <mesh name="hand_0" file="hand_0.obj"/>
    <mesh name="hand_1" file="hand_1.obj"/>
    <mesh name="hand_2" file="hand_2.obj"/>
    <mesh name="hand_3" file="hand_3.obj"/>
    <mesh name="hand_4" file="hand_4.obj"/>
    <mesh name="finger_0" file="finger_0.obj"/>
    <mesh name="finger_1" file="finger_1.obj"/>
    <mesh name="strawberry" file="strawberry.obj" scale="0.12 0.12 0.12"/>
    <mesh name="strawberry_leaves" file="strawberry_leaves.obj" scale="0.12 0.12 0.12"/>
    <mesh name="strawberry_collision" file="strawberry_collision.obj" scale="0.12 0.12 0.12"/>
  </asset>

  <worldbody>
    <geom name="floor" size="0 0 0.05" pos="0 0 0" type="plane" material="floor"/>
    <body name="link0" childclass="panda">
      <inertial pos="-0.041018 -0.00014 0.049974" quat="0.00630474 0.751245 0.00741774 0.659952" mass="0.629769" diaginertia="0.00430465 0.00387984 0.00313051"/>
      <geom class="visual" material="off_white" mesh="link0_0"/>
      <geom class="visual" material="black" mesh="link0_1"/>
      <geom class="visual" material="off_white" mesh="link0_2"/>
      <geom class="visual" material="black" mesh="link0_3"/>
      <geom class="visual" material="off_white" mesh="link0_4"/>
      <geom class="visual" material="black" mesh="link0_5"/>
      <geom class="visual" material="white" mesh="link0_7"/>
      <geom class="visual" material="white" mesh="link0_8"/>
      <geom class="visual" material="black" mesh="link0_9"/>
      <geom class="visual" material="off_white" mesh="link0_10"/>
      <geom class="visual" material="white" mesh="link0_11"/>
      <geom class="collision" mesh="link0_c"/>
      <body name="link1" pos="0 0 0.333">
        <inertial pos="0.003875 0.002081 -0.04762" quat="0.711549 0.00634377 -0.0131124 0.702485" mass="4.97068" diaginertia="0.707137 0.703435 0.00852456"/>
        <joint name="joint1" pos="0 0 0" axis="0 0 1"/>
        <geom class="visual" material="white" mesh="link1"/>
        <geom class="collision" mesh="link1_c"/>
        <site name="joint1" pos="0 0 0"/>
        <body name="link2" quat="0.707107 -0.707107 0 0">
          <inertial pos="-0.003141 -0.02872 0.003495" quat="-0.168175 0.828366 -0.122878 0.520027" mass="0.646926" diaginertia="0.0310326 0.0283001 0.00273425"/>
          <joint name="joint2" pos="0 0 0" axis="0 0 1" range="-1.7628 1.7628"/>
          <geom class="visual" material="white" mesh="link2"/>
          <geom class="collision" mesh="link2_c"/>
          <site name="joint2" pos="0 0 0"/>
          <body name="link3" pos="0 -0.316 0" quat="0.707107 0.707107 0 0">
            <inertial pos="0.027518 0.039252 -0.066502" quat="0.662769 -0.00678331 0.252053 0.705096" mass="3.2286" diaginertia="0.0415014 0.0414793 0.00124635"/>
            <joint name="joint3" pos="0 0 0" axis="0 0 1"/>
            <geom class="visual" material="white" mesh="link3_0"/>
            <geom class="visual" material="white" mesh="link3_1"/>
            <geom class="visual" material="white" mesh="link3_2"/>
            <geom class="visual" material="black" mesh="link3_3"/>
            <geom class="collision" mesh="link3_c"/>
            <site name="joint3" pos="0 0 0"/>
            <body name="link4" pos="0.0825 0 0" quat="0.707107 0.707107 0 0">
              <inertial pos="-0.05317 0.104419 0.027454" quat="0.65058 0.529822 -0.0962034 0.535518" mass="3.5879" diaginertia="0.0349596 0.0281483 0.0106201"/>
              <joint name="joint4" pos="0 0 0" axis="0 0 1" range="-3.0718 -0.0698"/>
              <geom class="visual" material="white" mesh="link4_0"/>
              <geom class="visual" material="white" mesh="link4_1"/>
              <geom class="visual" material="black" mesh="link4_2"/>
              <geom class="visual" material="white" mesh="link4_3"/>
              <geom class="collision" mesh="link4_c"/>
              <site name="joint4" pos="0 0 0"/>
              <body name="link5" pos="-0.0825 0.384 0" quat="0.707107 -0.707107 0 0">
                <inertial pos="-0.011953 0.041065 -0.038437" quat="0.987313 -0.0121954 0.0719187 -0.141037" mass="1.22595" diaginertia="0.0367625 0.0288531 0.00803437"/>
                <joint name="joint5" pos="0 0 0" axis="0 0 1"/>
                <geom class="visual" material="black" mesh="link5_0"/>
                <geom class="visual" material="white" mesh="link5_1"/>
                <geom class="visual" material="white" mesh="link5_2"/>
                <geom class="collision" mesh="link5_c0"/>
                <geom class="collision" mesh="link5_c1"/>
                <geom class="collision" mesh="link5_c2"/>
                <site name="joint5" pos="0 0 0"/>
                <body name="link6" quat="0.707107 0.707107 0 0">
                  <inertial pos="0.060149 -0.014117 -0.010517" quat="0.101075 0.59332 0.0287227 0.798079" mass="1.66656" diaginertia="0.00584276 0.00431037 0.00159787"/>
                  <joint name="joint6" pos="0 0 0" axis="0 0 1" range="-0.0175 3.7525"/>
                  <geom class="visual" material="off_white" mesh="link6_0"/>
                  <geom class="visual" material="white" mesh="link6_1"/>
                  <geom class="visual" material="black" mesh="link6_2"/>
                  <geom class="visual" material="white" mesh="link6_3"/>
                  <geom class="visual" material="white" mesh="link6_4"/>
                  <geom class="visual" material="white" mesh="link6_5"/>
                  <geom class="visual" material="white" mesh="link6_6"/>
                  <geom class="visual" material="light_blue" mesh="link6_7"/>
                  <geom class="visual" material="light_blue" mesh="link6_8"/>
                  <geom class="visual" material="black" mesh="link6_9"/>
                  <geom class="visual" material="black" mesh="link6_10"/>
                  <geom class="visual" material="white" mesh="link6_11"/>
                  <geom class="visual" material="green" mesh="link6_12"/>
                  <geom class="visual" material="white" mesh="link6_13"/>
                  <geom class="visual" material="black" mesh="link6_14"/>
                  <geom class="visual" material="black" mesh="link6_15"/>
                  <geom class="visual" material="white" mesh="link6_16"/>
                  <geom class="collision" mesh="link6_c"/>
                  <site name="joint6" pos="0 0 0"/>
                  <body name="link7" pos="0.088 0 0" quat="0.707107 0.707107 0 0">
                    <inertial pos="0.010517 -0.004252 0.061597" quat="0.992939 -0.0762041 0.0733595 -0.0537067" mass="0.735522" diaginertia="0.0127345 0.0101055 0.00451803"/>
                    <joint name="joint7" pos="0 0 0" axis="0 0 1"/>
                    <geom class="visual" material="white" mesh="link7_0"/>
                    <geom class="visual" material="black" mesh="link7_1"/>
                    <geom class="visual" material="black" mesh="link7_2"/>
                    <geom class="visual" material="black" mesh="link7_3"/>
                    <geom class="visual" material="black" mesh="link7_4"/>
                    <geom class="visual" material="black" mesh="link7_5"/>
                    <geom class="visual" material="black" mesh="link7_6"/>
                    <geom class="visual" material="white" mesh="link7_7"/>
                    <geom class="collision" mesh="link7_c"/>
                    <site name="joint7" pos="0 0 0"/>
                    <body name="camera_mount" pos="0 0 0.107">
                      <inertial pos="0 0 0" mass="0.5" diaginertia="0 0 0"/>
                      <!-- <geom class="visual" material="black" mesh="camera_mount"/> -->
                      <geom class="collision" mesh="camera_mount_c"/>
                      <body name="d435i_1" childclass="d435i" pos="-0.079892 0.03393 0.026921" quat="0.909844 0.16043 0.0664523 0.37687">
                        <!-- <geom class="d435i_visual" mass="0" material="IR_Lens" mesh="d435i_0"/>
                        <geom class="d435i_visual" mass="0" material="IR_Emitter_Lens" mesh="d435i_1"/>
                        <geom class="d435i_visual" mass="0" material="IR_Rim" mesh="d435i_2"/>
                        <geom class="d435i_visual" mass="0" material="IR_Lens" mesh="d435i_3"/>
                        <geom class="d435i_visual" mass="0" material="Cameras_Gray" mesh="d435i_4"/>
                        <geom class="d435i_visual" mass="0" material="Black_Acrylic" mesh="d435i_5"/>
                        <geom class="d435i_visual" mass="0" material="Black_Acrylic" mesh="d435i_6"/>
                        <geom class="d435i_visual" mass="0" material="RGB_Pupil" mesh="d435i_7"/>
                        <geom class="d435i_visual" mass="0.072" material="Metal_Casing" mesh="d435i_8"/> -->
                        <geom class="d435i_collision" size="0.00968864 0.0334784" pos="0.00145113 -0.000319327 -0.0135412" quat="0.029024 0.708312 0.0275527 0.704764" type="capsule" mass="0"/>
                        <site name="camera_1_site" pos="0.0325 0 -0.003" size="0.001" rgba="1 0 0 1"/>
                        <body name="wrist1" pos="0.0325 0 -0.003" quat="0 0 1 0">
                          <camera name="wrist1" pos="0 0 0" fovy="42"/>
                        </body>
                      </body>
                      <body name="d435i_2" childclass="d435i" pos="0.079892 -0.03393 0.026921" quat="0.376958 0.0664679 -0.160424 -0.909807">
                        <!-- <geom class="d435i_visual" mass="0" material="IR_Lens" mesh="d435i_0"/>
                        <geom class="d435i_visual" mass="0" material="IR_Emitter_Lens" mesh="d435i_1"/>
                        <geom class="d435i_visual" mass="0" material="IR_Rim" mesh="d435i_2"/>
                        <geom class="d435i_visual" mass="0" material="IR_Lens" mesh="d435i_3"/>
                        <geom class="d435i_visual" mass="0" material="Cameras_Gray" mesh="d435i_4"/>
                        <geom class="d435i_visual" mass="0" material="Black_Acrylic" mesh="d435i_5"/>
                        <geom class="d435i_visual" mass="0" material="Black_Acrylic" mesh="d435i_6"/>
                        <geom class="d435i_visual" mass="0" material="RGB_Pupil" mesh="d435i_7"/>
                        <geom class="d435i_visual" mass="0.072" material="Metal_Casing" mesh="d435i_8"/> -->
                        <geom class="d435i_collision" size="0.00968864 0.0334784" pos="0.00145113 -0.000319327 -0.0135412" quat="0.029024 0.708312 0.0275527 0.704764" type="capsule" mass="0"/>
                        <site name="camera_2_site" pos="0.0325 0 -0.003" quat="0 0 1 0" size="0.001" rgba="1 0 0 1"/>
                        <!-- <body name="wrist2" pos="0.0325 0 -0.003" quat="0 0 1 0">
                          <camera name="wrist2" pos="0 0 0" fovy="42"/>
                        </body> -->
                      </body>
                      <body name="hand" pos="0 0 0.0016" quat="0.92388 0 0 -0.382683">
                        <inertial pos="-0.01 0 0.03" mass="0.73" diaginertia="0.001 0.0025 0.0017"/>
                        <geom class="visual" material="off_white" mesh="hand_0"/>
                        <geom class="visual" material="black" mesh="hand_1"/>
                        <geom class="visual" material="black" mesh="hand_2"/>
                        <geom class="visual" material="white" mesh="hand_3"/>
                        <geom class="visual" material="off_white" mesh="hand_4"/>
                        <geom class="collision" mesh="hand_c"/>
                        <site name="attachment_site" pos="0 0 0" quat="0 0 0 1"/>
                        <body name="pinch" pos="0 0 0.105">
                          <site name="pinch" pos="0 0 0" size="0.01" group="3" rgba="1 0 0 1"/>
                        </body>
                        <body name="long_pinch" pos="0 0 0.15">
                          <site name="long_pinch" pos="0 0 0" size="0.01" group="3" rgba="1 0 0 1"/>
                        </body>
                        <body name="left_finger" pos="0 0 0.0584">
                          <inertial pos="0 0 0" mass="0.015" diaginertia="2.375e-06 2.375e-06 7.5e-07"/>
                          <joint name="finger_joint1" class="finger" pos="0 0 0" axis="0 1 0"/>
                          <geom class="visual" material="off_white" mesh="finger_0"/>
                          <geom class="collision" mesh="finger_0"/>
                          <geom name="left_finger_outer" class="collision" friction="2.0 0.1 0.05" mesh="gripper_long_outer" solref="0.01 0.5"/>
                          <geom name="left_finger_inner" class="collision" friction="2.0 0.1 0.05" mesh="gripper_long_inner" solref="0.01 0.5"/>
                          <geom class="visual" material="black" mesh="gripper_long"/>
                        </body>
                        <body name="right_finger" pos="0 0 0.0584" quat="0 0 0 1">
                          <inertial pos="0 0 0" mass="0.015" diaginertia="2.375e-06 2.375e-06 7.5e-07"/>
                          <joint name="finger_joint2" class="finger" pos="0 0 0" axis="0 1 0"/>
                          <geom class="visual" material="off_white" mesh="finger_0"/>
                          <geom class="collision" mesh="finger_0"/>
                          <geom name="right_finger_outer" class="collision" friction="2.0 0.1 0.05" mesh="gripper_long_outer" solref="0.01 0.5"/>
                          <geom name="right_finger_inner" class="collision" friction="2.0 0.1 0.05" mesh="gripper_long_inner" solref="0.01 0.5" group="4"/>
                          <geom class="visual" material="black" mesh="gripper_long"/>
                        </body>
                      </body>
                    </body>
                  </body>
                </body>
              </body>
            </body>
          </body>
        </body>
      </body>
    </body>
<!-- 
    <body name="front" pos="1.040 1.211 0.499" xyaxes="-0.811 0.585 -0.000 -0.007 -0.010 1.000">
      <camera name="front" pos="0 0 0" fovy="41"/>
    </body>
    <body name="side" pos="-0.151 -3.348 0.778" xyaxes="0.998 -0.056 -0.000 -0.001 -0.017 1.000"> 
      <camera name="side" pos="0 0 0" fovy="41"/>
    </body> -->
    <body name="light0" pos="0.3 0 1.6">
      <light pos="0 0 0" dir="0 0 -1" ambient="0.1 0.1 0.1" diffuse="0.2 0.2 0.2"/>
    </body>
    <body name="target" pos="0.15 0 0.5" quat="1 0 0 0" mocap="true">
      <geom name="target" size="0.03 0.03 0.03" type="box" contype="0" conaffinity="0" rgba="0.6 0.3 0.3 0"/>
    </body>

    <body name="vine1" pos="0.45 -0.03 0.9" quat="0.707388 0 0.706825 0">
      <body name="aB_first">
        <joint name="aJ_first" pos="0 0 0" type="ball" group="3" actuatorfrclimited="false" damping="0.001"/>
        <geom name="aG0" size="0.0007 0.015" pos="0.015 0 0" quat="0.707107 0 -0.707107 0" type="capsule" solref="0.01 0.1" mass="0.0001" rgba="0.208 0.337 0.149 1"/>
        <site name="aS_first" pos="0 0 0" group="3"/>
        <body name="aB_1" pos="0.03 0 0">
          <joint name="aJ_1" pos="0 0 0" type="ball" group="3" actuatorfrclimited="false" damping="0.001"/>
          <geom name="aG1" size="0.0007 0.015" pos="0.015 0 0" quat="0.707107 0 -0.707107 0" type="capsule" solref="0.01 0.1" mass="0.0001" rgba="0.208 0.337 0.149 1"/>
          <body name="aB_2" pos="0.03 0 0">
            <joint name="aJ_2" pos="0 0 0" type="ball" group="3" actuatorfrclimited="false" damping="0.001"/>
            <geom name="aG2" size="0.0007 0.015" pos="0.015 0 0" quat="0.707107 0 -0.707107 0" type="capsule" solref="0.01 0.1" mass="0.0001" rgba="0.208 0.337 0.149 1"/>
            <body name="aB_last" pos="0.03 0 0">
              <joint name="aJ_last" pos="0 0 0" type="ball" group="3" actuatorfrclimited="false" damping="0.001"/>
              <geom name="aG3" size="0.0007 0.015" pos="0.015 0 0" quat="0.707107 0 -0.707107 0" type="capsule" solref="0.01 0.1" mass="0.0001" rgba="0.208 0.337 0.149 1"/>
              <site name="aS_last" pos="0.03 0 0" group="3"/>      
              <body name="stem1" pos="0.091 -0.00024 0.00052" quat="0.707388 0 0 0.706825">
                <geom name="stem1" type="capsule" size="0.0007 0.012" pos="0.0002 0.049 -0.00055" euler="-1.57 0.0 0.0" rgba="0.208 0.337 0.149 1"/>
                <site name="stem1" pos="0.0001 0.054 -0.0004" size="0.0012" rgba="0 0 1 1" group="3"/>
                <site name="stem1_grasp" pos="0.0001 0.041 -0.0004" size="0.0012" rgba="0 0 1 1" group="3"/>
                <body name="block1" pos="0.0 0.001 0.0">
                  <site type="box" pos="0 0.015 0" size="0.015 0.02 0.015" group="3" rgba="0 1 0 0.2"/>
                  <geom name="block1" pos="0 0.03 0" type="sphere" size="0.01" density="400" rgba="0.55 0.1 0.1 1"/>
                </body>
              </body>
            </body>
          </body>
        </body>
      </body>
    </body>
  </worldbody>

  <contact>
    <exclude body1="aB_first" body2="aB_1"/>
    <exclude body1="aB_1" body2="aB_2"/>
    <exclude body1="aB_2" body2="aB_last"/>
    <exclude body1="aB_last" body2="stem1"/>
  </contact>

  <equality>
    <joint joint1="finger_joint1" joint2="finger_joint2" solimp="0.95 0.99 0.001" solref="0.005 1"/>
  </equality>

  <actuator>
    <general name="actuator1" class="panda" joint="joint1" forcerange="-87 87"/>
    <general name="actuator2" class="panda" joint="joint2" forcerange="-87 87"/>
    <general name="actuator3" class="panda" joint="joint3" forcerange="-87 87"/>
    <general name="actuator4" class="panda" joint="joint4" forcerange="-87 87"/>
    <general name="actuator5" class="panda" joint="joint5" forcerange="-12 12"/>
    <general name="actuator6" class="panda" joint="joint6" forcerange="-12 12"/>
    <general name="actuator7" class="panda" joint="joint7" forcerange="-12 12"/>
    <position name="fingers_actuator" joint="finger_joint1" kp="5000" kv="500" ctrlrange="0 0.04" forcerange="-100 100"/>
  </actuator>

  <sensor>
    <jointpos joint="joint1" name="panda/joint1_pos"/>
    <jointpos joint="joint2" name="panda/joint2_pos"/>
    <jointpos joint="joint3" name="panda/joint3_pos"/>
    <jointpos joint="joint4" name="panda/joint4_pos"/>
    <jointpos joint="joint5" name="panda/joint5_pos"/>
    <jointpos joint="joint6" name="panda/joint6_pos"/>
    <jointpos joint="joint7" name="panda/joint7_pos"/>
    <jointvel joint="joint1" name="panda/joint1_vel"/>
    <jointvel joint="joint2" name="panda/joint2_vel"/>
    <jointvel joint="joint3" name="panda/joint3_vel"/>
    <jointvel joint="joint4" name="panda/joint4_vel"/>
    <jointvel joint="joint5" name="panda/joint5_vel"/>
    <jointvel joint="joint6" name="panda/joint6_vel"/>
    <jointvel joint="joint7" name="panda/joint7_vel"/>
    <torque site="joint1" name="panda/joint1_torque"/>
    <torque site="joint2" name="panda/joint2_torque"/>
    <torque site="joint3" name="panda/joint3_torque"/>
    <torque site="joint4" name="panda/joint4_torque"/>
    <torque site="joint5" name="panda/joint5_torque"/>
    <torque site="joint6" name="panda/joint6_torque"/>
    <torque site="joint7" name="panda/joint7_torque"/>
    <force site="attachment_site" name="panda/wrist_force"/>
    <framepos objtype="site" objname="pinch" name="pinch_pos"/>
    <framequat objtype="site" objname="pinch" name="pinch_quat"/>
    <framelinvel objtype="site" objname="pinch" name="pinch_vel"/>
    <framepos objtype="site" objname="long_pinch" name="long_pinch_pos"/>
    <framequat objtype="site" objname="long_pinch" name="long_pinch_quat"/>
    <framelinvel objtype="site" objname="long_pinch" name="long_pinch_vel"/>
    <framepos objtype="site" objname="stem1_grasp" name="block1_pos"/>
    <framequat objtype="geom" objname="block1" name="block_quat"/>
  </sensor>
</mujoco>